Workbook
Name Calendar: daysAndWks + DateOfFirst - WEEKDAY(DateOfFirst,2)
Name DateOfFirst: DATE(YEAR(#REF!),MONTH(#REF!),1)
Name daysAndWks: COLUMN(OFFSET(INDIRECT("$A$1"),0,0,1,42))-1
Name kada: daysAndWks + kada1 - WEEKDAY(kada1,2)
Name kada1: DATE(YEAR(#REF!),MONTH(#REF!),1)
Name kada3: [1]Mini!$C$6:$AR$6
Name m1_: #REF!
Name m10_: #REF!
Name m11_: #REF!
Name m12_: #REF!
Name m2_: #REF!
Name m3_: #REF!
Name m4_: #REF!
Name m5_: #REF!
Name m6_: #REF!
Name m7_: #REF!
Name m8_: #REF!
Name m9_: #REF!
Name year: [1]Full!$D$3

Sheet PM schedule 2019 
D1: 53 WEEK PM SCHEDULE YEAR 2019 BHARTI AIRTEL (DTH) BANGALORE
A2: SL No | B2: Current date | E2: Week | F2: 1 | G2: 2 | H2: 3 | I2: 4 | J2: 5 | K2: 6 | L2: 7 | M2: 8 | N2: 9 | O2: 10 | P2: 11 | Q2: 12 | R2: 13 | S2: 14 | T2: 15 | U2: 16 | V2: 17 | W2: 18 | X2: 19 | Y2: 20 | Z2: 21 | AA2: 22 | AB2: 23 | AC2: 24 | AD2: 25 | AE2: 26 | AF2: 27 | AG2: 28 | AH2: 29 | AI2: 30 | AJ2: 31 | AK2: 32 | AL2: 33 | AM2: 34 | AN2: 35 | AO2: 36 | AP2: 37 | AQ2: 38 | AR2: 39 | AS2: 40 | AT2: 41 | AU2: 42 | AV2: 43 | AW2: 44 | AX2: 45 | AY2: 46 | AZ2: 47 | BA2: 48 | BB2: 49 | BC2: 50 | BD2: 51 | BE2: 52 | BF2: 53
B3: =TODAY() -> 43472 | F3: JAN | K3: FEB | O3: MAR | S3: APR | X3: MAY | AB3: JUNE | AF3: JULY | AK3: AUG | AO3: SEP | AT3: OCT | AX3: NOV | BB3: DEC
B4: Legend OTHER COLOURS ARE INTERNAL PM M MONTHLY Q QUARTERLY H HALF YEARLY Y YEARLY | C4: LAST PM COMPLETION DATE | D4: Location | E4: Monday | G4: 7 | H4: 14 | I4: 21 | J4: 28 | K4: 4 | L4: 11 | M4: 18 | N4: 25 | O4: 4 | P4: 11 | Q4: 18 | R4: 25 | S4: 1 | T4: 8 | U4: 15 | V4: 22 | W4: 29 | X4: 6 | Y4: 13 | Z4: 20 | AA4: 27 | AB4: 3 | AC4: 10 | AD4: 17 | AE4: 24 | AF4: 1 | AG4: 8 | AH4: 15 | AI4: 22 | AJ4: 29 | AK4: 5 | AL4: 12 | AM4: 19 | AN4: 26 | AO4: 2 | AP4: 9 | AQ4: 16 | AR4: 23 | AS4: 30 | AT4: 7 | AU4: 14 | AV4: 21 | AW4: 28 | AX4: 4 | AY4: 11 | AZ4: 18 | BA4: 25 | BB4: 2 | BC4: 9 | BD4: 16 | BE4: 23 | BF4: 30
E5: Tuesday | F5: 1 | G5: 8 | H5: 15 | I5: 22 | J5: 29 | K5: 5 | L5: 12 | M5: 19 | N5: 26 | O5: 5 | P5: 12 | Q5: 19 | R5: 26 | S5: 2 | T5: 9 | U5: 16 | V5: 23 | W5: 30 | X5: 7 | Y5: 14 | Z5: 21 | AA5: 28 | AB5: 4 | AC5: 11 | AD5: 18 | AE5: 25 | AF5: 2 | AG5: 9 | AH5: 16 | AI5: 23 | AJ5: 30 | AK5: 6 | AL5: 13 | AM5: 20 | AN5: 27 | AO5: 3 | AP5: 10 | AQ5: 17 | AR5: 24 | AS5: 1 | AT5: 8 | AU5: 15 | AV5: 22 | AW5: 29 | AX5: 5 | AY5: 12 | AZ5: 19 | BA5: 26 | BB5: 3 | BC5: 10 | BD5: 17 | BE5: 24 | BF5: 31
E6: Wednesday | F6: 2 | G6: 9 | H6: 16 | I6: 23 | J6: 30 | K6: 6 | L6: 13 | M6: 20 | N6: 27 | O6: 6 | P6: 13 | Q6: 20 | R6: 27 | S6: 3 | T6: 10 | U6: 17 | V6: 24 | W6: 1 | X6: 8 | Y6: 15 | Z6: 22 | AA6: 29 | AB6: 5 | AC6: 12 | AD6: 19 | AE6: 26 | AF6: 3 | AG6: 10 | AH6: 17 | AI6: 24 | AJ6: 31 | AK6: 7 | AL6: 14 | AM6: 21 | AN6: 28 | AO6: 4 | AP6: 11 | AQ6: 18 | AR6: 25 | AS6: 2 | AT6: 9 | AU6: 16 | AV6: 23 | AW6: 30 | AX6: 6 | AY6: 13 | AZ6: 20 | BA6: 27 | BB6: 4 | BC6: 11 | BD6: 18 | BE6: 25
E7: Thursday | F7: 3 | G7: 10 | H7: 17 | I7: 24 | J7: 31 | K7: 7 | L7: 14 | M7: 21 | N7: 28 | O7: 7 | P7: 14 | Q7: 21 | R7: 28 | S7: 4 | T7: 11 | U7: 18 | V7: 25 | W7: 2 | X7: 9 | Y7: 16 | Z7: 23 | AA7: 30 | AB7: 6 | AC7: 13 | AD7: 20 | AE7: 27 | AF7: 4 | AG7: 11 | AH7: 18 | AI7: 25 | AJ7: 1 | AK7: 8 | AL7: 15 | AM7: 22 | AN7: 29 | AO7: 5 | AP7: 12 | AQ7: 19 | AR7: 26 | AS7: 3 | AT7: 10 | AU7: 17 | AV7: 24 | AW7: 31 | AX7: 7 | AY7: 14 | AZ7: 21 | BA7: 28 | BB7: 5 | BC7: 12 | BD7: 19 | BE7: 26
E8: Friday | F8: 4 | G8: 11 | H8: 18 | I8: 25 | J8: 1 | K8: 8 | L8: 15 | M8: 22 | N8: 1 | O8: 8 | P8: 15 | Q8: 22 | R8: 29 | S8: 5 | T8: 12 | U8: 19 | V8: 26 | W8: 3 | X8: 10 | Y8: 17 | Z8: 24 | AA8: 31 | AB8: 7 | AC8: 14 | AD8: 21 | AE8: 28 | AF8: 5 | AG8: 12 | AH8: 19 | AI8: 26 | AJ8: 2 | AK8: 9 | AL8: 16 | AM8: 23 | AN8: 30 | AO8: 6 | AP8: 13 | AQ8: 20 | AR8: 27 | AS8: 4 | AT8: 11 | AU8: 18 | AV8: 25 | AW8: 1 | AX8: 8 | AY8: 15 | AZ8: 22 | BA8: 29 | BB8: 6 | BC8: 13 | BD8: 20 | BE8: 27
E9: Saturday | F9: 5 | G9: 12 | H9: 19 | I9: 26 | J9: 2 | K9: 9 | L9: 16 | M9: 23 | N9: 2 | O9: 9 | P9: 16 | Q9: 23 | R9: 30 | S9: 6 | T9: 13 | U9: 20 | V9: 27 | W9: 4 | X9: 11 | Y9: 18 | Z9: 25 | AA9: 1 | AB9: 8 | AC9: 15 | AD9: 22 | AE9: 29 | AF9: 6 | AG9: 13 | AH9: 20 | AI9: 27 | AJ9: 3 | AK9: 10 | AL9: 17 | AM9: 24 | AN9: 31 | AO9: 7 | AP9: 14 | AQ9: 21 | AR9: 28 | AS9: 5 | AT9: 12 | AU9: 19 | AV9: 26 | AW9: 2 | AX9: 9 | AY9: 16 | AZ9: 23 | BA9: 30 | BB9: 7 | BC9: 14 | BD9: 21 | BE9: 28
B10: EQUIPMENT | E10: Sunday | F10: 6 | G10: 13 | H10: 20 | I10: 27 | J10: 3 | K10: 10 | L10: 17 | M10: 24 | N10: 3 | O10: 10 | P10: 17 | Q10: 24 | R10: 31 | S10: 7 | T10: 14 | U10: 21 | V10: 28 | W10: 5 | X10: 12 | Y10: 19 | Z10: 26 | AA10: 2 | AB10: 9 | AC10: 16 | AD10: 23 | AE10: 30 | AF10: 7 | AG10: 14 | AH10: 21 | AI10: 28 | AJ10: 4 | AK10: 11 | AL10: 18 | AM10: 25 | AN10: 1 | AO10: 8 | AP10: 15 | AQ10: 22 | AR10: 29 | AS10: 6 | AT10: 13 | AU10: 20 | AV10: 27 | AW10: 3 | AX10: 10 | AY10: 17 | AZ10: 24 | BA10: 1 | BB10: 8 | BC10: 15 | BD10: 22 | BE10: 29
A11: Vendor PM
A12: 1 | B12: Antenna 11.3m | C12: =FR.CO.08!I44 -> 42348 | D12: Terrace | J12: Q | AA12: Q | AN12: Q | BA12: Q
A13: 2 | B13: KHPA [ADSAT} | C13: =FR.CO.08!I39 -> 42363 | D13: RF Room | Q13: Q | AD13: Q | AQ13: Q | BD13: Q
A14: 3 | B14: CAS Equiment's | D14: HE Room | N14: Q | AC14: Q | AQ14: Q | BD14: Q
A15: 4 | B15: Spectrum Analyzer(Calibration) | C15: =FR.CO.08!I41 -> 42461 | D15: RF Room | P15: Y
A16: Internal PM
A17: 5 | B17: HE Equipments | C17: =FR.CO.08!I52 -> 0 | D17: HE Room | O17: Q | AD17: Q | AR17: Q | BB17: Q
A18: 6 | B18: RO antenna's [1 - 9] | C18: =FR.CO.08!I40 -> 42437 | D18: Terrace | P18: Q | AB18: Q | AP18: Q | BC18: Q
A19: 7 | B19: RF Equipments | C19: =FR.CO.08!I51 -> 0 | D19: RF Room | J19: Q | S19: Q | AB19: Q | AO19: Q | BB19: Q

Sheet FR.CO.08
B1: Bharti Telemedia Ltd | J1: FR.CO.08, Rev-00
C2: Preventive Maintenance Scheduling & Follow-Up
C3: Deptt: | D3: DTH
C4: Reviewd By : | D4: Kabbur
C5: [Updation of this check sheet needs to be done on weekly basis]
A6: # | B6: Equipment Name | C6: Equipment Sr. No. | D6: Vendor | E6: Commissioning Date | F6: Warranty Period | G6: PM Frequency | H6: Last PM Carried on Date(enter mm/dd/yyyy) | I6: Next PM Due Date | J6: Remarks
A7: 1 | B7: Main LT PANEL | C7: PSPLC75010901 | D7: PACE electricals | E7: NA | F7: June’09 to June’10 | G7: Quarterly | H7: 42358 | I7: =DATE(YEAR(H7), MONTH(H7)+3, DAY(H7)) -> 42449
A8: 2 | B8: UPS I/P & O/P PANEL | C8: PSPLC75010902 | D8: PACE electricals | E8: NA | F8: June’09 to June’10 | G8: Quarterly | H8: 42358 | I8: =DATE(YEAR(H8), MONTH(H8)+3, DAY(H8)) -> 42449
A9: 3 | B9: BLOWER STARTER PANEL | C9: PSPLC75010903 | D9: PACE electricals | E9: NA | F9: June’09 to June’10 | G9: Quarterly | H9: 42358 | I9: =DATE(YEAR(H9), MONTH(H9)+3, DAY(H9)) -> 42449
A10: 4 | B10: UPS, RP & UPS DISTRIBUTION BOARD | C10: NA | D10: PACE electricals | E10: NA | F10: June’09 to June’10 | G10: Quarterly | H10: 42358 | I10: =DATE(YEAR(H10), MONTH(H10)+3, DAY(H10)) -> 42449
A11: 5 | B11: UPS 200 KVA-1 HIPULSE 7400M | C11: 200812HI3236 | D11: Emerson | E11: 30/04/2009 | F11: 30-04-2009 to 29-04-2012 | G11: Quarterly | H11: 42297 | I11: =DATE(YEAR(H11), MONTH(H11)+3, DAY(H11)) -> 42389
A12: 6 | B12: UPS 200 KVA-2 HIPULSE 7400M | C12: 200811HI3090 | D12: Emerson | E12: 30/04/2009 | F12: 30-04-2009 to 29-04-2012 | G12: Quarterly | H12: 42297 | I12: =DATE(YEAR(H12), MONTH(H12)+3, DAY(H12)) -> 42389
A13: 7 | B13: UPS 30 KVA-3 HIPULSE 7400M | C13: 2008117M4412 | D13: Emerson | E13: 30/04/2009 | F13: 30-04-2009 to 29-04-2012 | G13: Quarterly | H13: 42297 | I13: =DATE(YEAR(H13), MONTH(H13)+3, DAY(H13)) -> 42389
A14: 8 | B14: Active Filter UPS -1-150Amp | C14: NA | D14: Emerson | E14: NA | F14: 30-04-2009 to 29-04-2012 | G14: Quarterly | H14: 42297 | I14: =DATE(YEAR(H14), MONTH(H14)+3, DAY(H14)) -> 42389
A15: 9 | B15: Active Filter UPS -2 -150 Amp | C15: NA | D15: Emerson | E15: NA | F15: 30-04-2009 to 29-04-2012 | G15: Quarterly | H15: 42297 | I15: =DATE(YEAR(H15), MONTH(H15)+3, DAY(H15)) -> 42389
A16: 10 | B16: Battery Bank UPS 200 KVA - 1 | C16: 8W0807 | D16: Emerson | E16: 30/04/2009 | F16: 30-04-2009 to 29-04-2012 | G16: Quarterly | H16: 42297 | I16: =DATE(YEAR(H16), MONTH(H16)+3, DAY(H16)) -> 42389
A17: 11 | B17: Battery Bank UPS 200 KVA - 2 | C17: 8W0807 | D17: Emerson | E17: 30/04/2009 | F17: 30-04-2009 to 29-04-2012 | G17: Quarterly | H17: 42297 | I17: =DATE(YEAR(H17), MONTH(H17)+3, DAY(H17)) -> 42389
A18: 12 | B18: Battery Bank UPS 30 KVA - 1 | C18: HK16HI7YK4 | D18: Emerson | E18: 30/04/2009 | F18: 30-04-2009 to 29-04-2012 | G18: Quarterly | H18: 42297 | I18: =DATE(YEAR(H18), MONTH(H18)+3, DAY(H18)) -> 42389
A19: 13 | B19: Headend PAC 1 PEX 380FA100 | C19: 090740260111 | D19: Emerson | E19: 16/06/2009 | F19: 16-06-2009 to 15-06-2010 | G19: Bi monthly | H19: 42329 | I19: =DATE(YEAR(H19), MONTH(H19)+2, DAY(H19)) -> 42390
A20: 14 | B20: Headend PAC 2 PEX 380FA100 | C20: 090740260112 | D20: Emerson | E20: 16/06/2009 | F20: 16-06-2009 to 15-06-2010 | G20: Bi monthly | H20: 42329 | I20: =DATE(YEAR(H20), MONTH(H20)+2, DAY(H20)) -> 42390
A21: 15 | B21: Headend PAC 3 PEX 380FA100 | C21: 090740260113 | D21: Emerson | E21: 16/06/2009 | F21: 16-06-2009 to 15-06-2010 | G21: Bi monthly | H21: 42329 | I21: =DATE(YEAR(H21), MONTH(H21)+2, DAY(H21)) -> 42390
A22: 16 | B22: Headend PAC 4 PEX 380FA100 | C22: 090740260114 | D22: Emerson | E22: 16/06/2009 | F22: 16-06-2009 to 15-06-2010 | G22: Bi monthly | H22: 42329 | I22: =DATE(YEAR(H22), MONTH(H22)+2, DAY(H22)) -> 42390
A23: 17 | B23: Headend PAC 5 PEX 380FA100 | C23: 090740260115 | D23: Emerson | E23: 16/06/2009 | F23: 16-06-2009 to 15-06-2010 | G23: Bi monthly | H23: 42329 | I23: =DATE(YEAR(H23), MONTH(H23)+2, DAY(H23)) -> 42390
A24: 18 | B24: RF Room 1 PAC1 PEX130FA100 | C24: 090640130209 | D24: Emerson | E24: 16/06/2009 | F24: 16-06-2009 to 15-06-2010 | G24: Bi monthly | H24: 42329 | I24: =DATE(YEAR(H24), MONTH(H24)+2, DAY(H24)) -> 42390
A25: 19 | B25: RF Room 2 PAC1 PEX130FA100 | C25: 090640130210 | D25: Emerson | E25: 16/06/2009 | F25: 16-06-2009 to 15-06-2010 | G25: Bi monthly | H25: 42329 | I25: =DATE(YEAR(H25), MONTH(H25)+2, DAY(H25)) -> 42390
A26: 20 | B26: RF Room 3 PAC1 PEX130FA100 | C26: 090640130211 | D26: Emerson | E26: 16/06/2009 | F26: 16-06-2009 to 15-06-2010 | G26: Bi monthly | H26: 42329 | I26: =DATE(YEAR(H26), MONTH(H26)+2, DAY(H26)) -> 42390
A27: 21 | B27: UPS Room1PAC 1 PEX130FA100 | C27: 090740125203 | D27: Emerson | E27: 16/06/2009 | F27: 16-06-2009 to 15-06-2010 | G27: Bi monthly | H27: 42329 | I27: =DATE(YEAR(H27), MONTH(H27)+2, DAY(H27)) -> 42390
A28: 22 | B28: UPS Room1PAC 2 PEX130FA100 | C28: 090740125204 | D28: Emerson | E28: 16/06/2009 | F28: 16-06-2009 to 15-06-2010 | G28: Bi monthly | H28: 42329 | I28: =DATE(YEAR(H28), MONTH(H28)+2, DAY(H28)) -> 42390
A29: 23 | B29: UPS Room1 PAC 3PEX130FA100 | C29: 090740125205 | D29: Emerson | E29: 16/06/2009 | F29: 16-06-2009 to 15-06-2010 | G29: Bi monthly | H29: 42329 | I29: =DATE(YEAR(H29), MONTH(H29)+2, DAY(H29)) -> 42390
A30: 24 | B30: CAS Room PAC PEC113FA100 | C30: 090740113107 | D30: Emerson | E30: 16/06/2009 | F30: 16-06-2009 to 15-06-2010 | G30: Bi monthly | H30: 42329 | I30: =DATE(YEAR(H30), MONTH(H30)+2, DAY(H30)) -> 42390
A31: 25 | B31: FM 200 Notifier Alarm System | C31: 15219-G | D31: Newage | E31: 30/05/2009 | F31: 31-05-2009 to 30-05-2010 | G31: Quarterly | H31: 42291 | I31: =DATE(YEAR(H31), MONTH(H31)+3, DAY(H31)) -> 42383
A32: 26 | B32: Monitor Room AHU 1 | C32: NA | D32: Unique | E32: 16/06/09 | F32: 16/06/2009 to 16/06/2010 | G32: Quarterly | H32: 42358 | I32: =DATE(YEAR(H32), MONTH(H32)+3, DAY(H32)) -> 42449
A33: 27 | B33: Monitor Room AHU 2 | C33: NA | D33: Unique | E33: 18/06/09 | F33: 18/06/2009 to 18/06/2010 | G33: Quarterly | H33: 42358 | I33: =DATE(YEAR(H33), MONTH(H33)+3, DAY(H33)) -> 42449
A34: 28 | B34: Office area AHU 1 | C34: NA | D34: Unique | E34: 18/06/09 | F34: 18/06/2009 to 18/06/2010 | G34: Quarterly | H34: 42358 | I34: =DATE(YEAR(H34), MONTH(H34)+3, DAY(H34)) -> 42449
A35: 29 | B35: RF Room INLET Fan 1 | C35: NA | D35: Unique | E35: 18/06/09 | F35: 18/06/2009 to 18/06/2010 | G35: Monthly | H35: 42358 | I35: =DATE(YEAR(H35), MONTH(H35)+1, DAY(H35)) -> 42389
A36: 30 | B36: RF Room INLET Fan 2 | C36: NA | D36: Unique | E36: 18/06/09 | F36: 18/06/2009 to 18/06/2010 | G36: Monthly | H36: 42358 | I36: =DATE(YEAR(H36), MONTH(H36)+1, DAY(H36)) -> 42389
A37: 31 | B37: RF Room Exaust Fan 1 | C37: NA | D37: Unique | E37: 18/06/09 | F37: 18/06/2009 to 18/06/2010 | G37: Monthly | H37: 42358 | I37: =DATE(YEAR(H37), MONTH(H37)+1, DAY(H37)) -> 42389
A38: 32 | B38: RF Room Exhaust Fan 2 | C38: NA | D38: Unique | E38: 18/06/09 | F38: 18/06/2009 to 18/06/2010 | G38: Monthly | H38: 42358 | I38: =DATE(YEAR(H38), MONTH(H38)+1, DAY(H38)) -> 42389
A39: 33 | B39: KHPA | C39: SF97XXXX | D39: CPI | E39: 23/07/2009 | F39: 23/07/2009 to 23/01/2011 | G39: Quarterly | H39: 42272 | I39: =DATE(YEAR(H39), MONTH(H39)+3, DAY(H39)) -> 42363
A40: 34 | B40: RO antenna's 1-7 | D40: SPACELINK | G40: Quarterly | H40: 42346 | I40: =DATE(YEAR(H40), MONTH(H40)+3, DAY(H40)) -> 42437
...
